<?xml version="1.0"?>
<robot xmlns:xacro="http://www.ros.org/wiki/xacro">

    <xacro:include filename="inertial_macros.xacro"/>

    <material name="white">
        <color rgba=" 1 1 1 1"/>
    </material>

    <material name="orange">
        <color rgba=" 1 0.3 0.1 1"/>
    </material>For

    <material name="blue">
        <color rgba=" 0.2 0.2 1 1"/>
    </material>

    <material name="black">
        <color rgba="0 0 0 1"/>
    </material>

    <material name="red">
        <color rgba="1 0 0 1"/>
    </material>
 
    <link name="base_link">

    </link>
    <joint name="base_footprint_joint" type = "fixed">
      <parent link="base_link"/>
      <child link="base_footprint"/>
      <origin xyz="0 0 0" rpy="0 0 0"/>
    </joint>

    <link name="base_footprint">
      
    </link>
    
    
    <joint name="chassis_joint" type="fixed">
        <parent link="base_link"/>
        <child link="chassis"/>
        <origin xyz="0 0 0"/>
    </joint>

    <link name="chassis">
        <visual>
            <origin xyz="0 0 0.0381"/>
            <geometry>
                <box size="0.178 0.127 0.0762"/>
            </geometry>
            <material name="white"/>
        </visual>
        <collision>
            <origin xyz="0 0 0.0381"/>
            <geometry>
                <box size="0.178 0.127 0.0762"/>
            </geometry>
        </collision>
        <xacro:inertial_box mass="0.68" x="0.178" y="0.127" z="0.0762">
            <origin xyz="0 0 0.0381" rpy="0 0 0"/>
        </xacro:inertial_box>
        
    </link>

    <gazebo reference="chassis">
        <material>Gazebo/White</material>
    </gazebo>

    <joint name="left_front_wheel_joint" type="continuous">
        <parent link="base_link"/>
        <child link="left_front_wheel"/>
        <origin xyz="0.122 .02 -0.125" rpy="-${pi/2} 0 0"/>
        <axis xyz="0 0 1"/>
    </joint>
    
    <link name="left_front_wheel">
        <visual>
            <origin xyz="0 0 0.0381"/>
            <geometry>
                <cylinder radius="0.05" length="0.08"/>
            </geometry>
            <material name="blue"/>
        </visual>
        <collision>
            <origin xyz="0 0 0.0381"/>
            <geometry>
                <cylinder radius="0.05" length="0.08"/>
            </geometry>
        </collision>
        <xacro:inertial_cylinder mass="0.1" length="0.08" radius=".05">
            <origin xyz="0 0 0.0" rpy="0 0 0"/>
        </xacro:inertial_cylinder>
    </link>
    <gazebo reference="left_front_wheel">
        <material>Gazebo/Blue</material>
    </gazebo>


    <joint name="right_front_wheel_joint" type="continuous">
        <parent link="base_link"/>
        <child link="right_front_wheel"/>
        <origin xyz="0.122 -.02 -0.125" rpy="${pi/2} 0 0"/>
        <axis xyz="0 0 -1"/>
    </joint>
    
    <link name="right_front_wheel">
        <visual>
            <origin xyz="0 0 0.0381"/>
            <geometry>
                <cylinder radius="0.05" length="0.08"/>
            </geometry>
            <material name="blue"/>
        </visual>
        <collision>
            <origin xyz="0 0 0.0381"/>
            <geometry>
                <cylinder radius="0.05" length="0.08"/>
            </geometry>
        </collision>
        <xacro:inertial_cylinder mass="0.1" length="0.08" radius=".05">
            <origin xyz="0 0 0.0" rpy="0 0 0"/>
        </xacro:inertial_cylinder>
    </link>

    <gazebo reference="right_front_wheel">
        <material>Gazebo/Blue</material>
    </gazebo>

    <joint name="left_middle_joint" type="continuous">
        <parent link="base_link"/>
        <child link="left_wheel"/>
        <origin xyz="0 .02 -0.125" rpy="-${pi/2} 0 0"/>
        <axis xyz="0 0 1"/>
    </joint>
    
    <link name="left_wheel">
        <visual>
            <origin xyz="0 0 0.0381"/>
            <geometry>
                <cylinder radius="0.05" length="0.08"/>
            </geometry>
            <material name="blue"/>
        </visual>
        <collision>
            <origin xyz="0 0 0.0381"/>
            <geometry>
                <cylinder radius="0.05" length="0.08"/>
            </geometry>
        </collision>
        <xacro:inertial_cylinder mass="0.1" length="0.08" radius="0.05">
            <origin xyz="0 0 0.0" rpy="0 0 0"/>
        </xacro:inertial_cylinder>
    </link>
    <gazebo reference="left_wheel">
        <material>Gazebo/Blue</material>
    </gazebo>


    <joint name="right_wheel_joint" type="continuous">
        <parent link="base_link"/>
        <child link="right_wheel"/>
        <origin xyz="0 -.02 -0.125" rpy="${pi/2} 0 0"/>
        <axis xyz="0 0 -1"/>
    </joint>
    
    <link name="right_wheel">
        <visual>
            <origin xyz="0 0 0.0381"/>
            <geometry>
                <cylinder radius="0.05" length="0.08"/>
            </geometry>
            <material name="blue"/>
        </visual>
        <collision>
            <origin xyz="0 0 0.0381"/>
            <geometry>
                <cylinder radius="0.05" length="0.08"/>
            </geometry>
        </collision>
        <xacro:inertial_cylinder mass="0.1" length="0.08" radius=".05">
            <origin xyz="0 0 0.0" rpy="0 0 0"/>
        </xacro:inertial_cylinder>
    </link>

    <gazebo reference="right_wheel">
        <material>Gazebo/Blue</material>
    </gazebo>

    <joint name="left_back_wheel_joint" type="continuous">
        <parent link="base_link"/>
        <child link="left_back_wheel"/>
        <origin xyz="-0.118 .03 -0.125" rpy="-${pi/2} 0 0"/>
        <axis xyz="0 0 1"/>
    </joint>
    
    <link name="left_back_wheel">
        <visual>
            <origin xyz="0 0 0.0381"/>
            <geometry>
                <cylinder radius="0.05" length="0.08"/>
            </geometry>
            <material name="blue"/>
        </visual>
        <collision>
            <origin xyz="0 0 0.0381"/>
            <geometry>
                <cylinder radius="0.05" length="0.08"/>
            </geometry>
        </collision>
        <xacro:inertial_cylinder mass="0.1" length="0.08" radius=".05">
            <origin xyz="0 0 0" rpy="0 0 0"/>
        </xacro:inertial_cylinder>
    </link>

    <gazebo reference="left_back_wheel">
        <material>Gazebo/Blue</material>
    </gazebo>

    <joint name="right_back_wheel_joint" type="continuous">
        <parent link="base_link"/>
        <child link="right_back_wheel"/>
        <origin xyz=" -0.118 -.03 -0.125" rpy="${pi/2} 0 0"/>
        <axis xyz="0 0 -1"/>
    </joint>
    
    <link name="right_back_wheel">
        <visual>
            <origin xyz="0 0 0.0381"/>
            <geometry>
                <cylinder radius="0.05" length="0.08"/>
            </geometry>
            <material name="blue"/>
        </visual>
        <collision>
            <origin xyz="0 0 0.0381"/>
            <geometry>
                <cylinder radius="0.05" length="0.08"/>
            </geometry>
        </collision>
        <xacro:inertial_cylinder mass="0.1" length="0.08" radius=".05">
            <origin xyz="0 0 0.0" rpy="0 0 0"/>
        </xacro:inertial_cylinder>
    </link>


    <gazebo reference="right_back_wheel">
        <material>Gazebo/Blue</material>

    </gazebo>

</robot>
<!-- This URDF was automatically created by SolidWorks to URDF Exporter! Originally created by Stephen Brawner (brawner@gmail.com) 
     Commit Version: 1.6.0-4-g7f85cfe  Build Version: 1.6.7995.38578
     For more information, please see http://wiki.ros.org/sw_urdf_exporter -->
<!-- <robot xmlns:xacro="http://www.ros.org/wiki/xacro">

    <xacro:include filename="inertial_macros.xacro"/>
    name="my_bot">
  <link
    name="base_link">
    <inertial>
      <origin
        xyz="0.18096 0.13921 0.16741"
        rpy="0 0 0" />
      <mass
        value="0.39929" />
      <inertia
        ixx="0.0011054"
        ixy="9.6361E-07"
        ixz="1.8822E-16"
        iyy="0.0023993"
        iyz="1.9082E-15"
        izz="0.0017729" />
    </inertial>
    <visual>
      <origin
        xyz="0 0 0"
        rpy="0 0 0" />
      <geometry>
        <mesh
          filename="package://ARGGG/meshes/base_link.STL" />
      </geometry>
      <material
        name="">
        <color
          rgba="0.89804 0.91373 0.92549 1" />
      </material>
    </visual>
    <collision>
      <origin
        xyz="0 0 0"
        rpy="0 0 0" />
      <geometry>
        <mesh
          filename="package://ARGGG/meshes/base_link.STL" />
      </geometry>
    </collision>
  </link>
  <link
    name="Empty_Link1">
    <inertial>
      <origin
        xyz="0.028575 8.5594E-06 -0.0635"
        rpy="0 0 0" />
      <mass
        value="0.019306" />
      <inertia
        ixx="1.2326E-06"
        ixy="3.2731E-15"
        ixz="3.2296E-22"
        iyy="1.2326E-06"
        iyz="-1.6399E-22"
        izz="1.9461E-06" />
    </inertial>
    <visual>
      <origin
        xyz="0 0 0"
        rpy="0 0 0" />
      <geometry>
        <mesh
          filename="package://ARGGG/meshes/Empty_Link1.STL" />
      </geometry>
      <material
        name="">
        <color
          rgba="0.79216 0.81961 0.92941 1" />
      </material>
    </visual>
    <collision>
      <origin
        xyz="0 0 0"
        rpy="0 0 0" />
      <geometry>
        <mesh
          filename="package://ARGGG/meshes/Empty_Link1.STL" />
      </geometry>
    </collision>
  </link>
  <joint
    name="1"
    type="continuous">
    <origin
      xyz="0.18119 -0.23091 0.14969"
      rpy="1.5708 0.00029954 0" />
    <parent
      link="base_link" />
    <child
      link="Empty_Link1" />
    <axis
      xyz="0 0 0" />
  </joint>
  <link
    name="Empty_Link2">
    <inertial>
      <origin
        xyz="0.12139 0.026219 -0.0762"
        rpy="0 0 0" />
      <mass
        value="0.22286" />
      <inertia
        ixx="0.00030845"
        ixy="0.0002357"
        ixz="1.2212E-12"
        iyy="0.0010487"
        iyz="-8.3429E-12"
        izz="0.0013512" />
    </inertial>
    <visual>
      <origin
        xyz="0 0 0"
        rpy="0 0 0" />
      <geometry>
        <mesh
          filename="package://ARGGG/meshes/Empty_Link2.STL" />
      </geometry>
      <material
        name="">
        <color
          rgba="0.49804 0.49804 0.49804 1" />
      </material>
    </visual>
    <collision>
      <origin
        xyz="0 0 0"
        rpy="0 0 0" />
      <geometry>
        <mesh
          filename="package://ARGGG/meshes/Empty_Link2.STL" />
      </geometry>
    </collision>
  </link>
  <joint
    name="2"
    type="continuous">
    <origin
      xyz="-0.044434 -0.053353 0.0127"
      rpy="0 0 0.00029954" />
    <parent
      link="Empty_Link1" />
    <child
      link="Empty_Link2" />
    <axis
      xyz="0 0 0" />
  </joint>
  <link
    name="Empty_Link3">
    <inertial>
      <origin
        xyz="0 1.3567E-06 0.003175"
        rpy="0 0 0" />
      <mass
        value="0.0042119" />
      <inertia
        ixx="3.2106E-07"
        ixy="5.1796E-13"
        ixz="5.3789E-12"
        iyy="3.2146E-07"
        iyz="-6.6644E-18"
        izz="6.1434E-07" />
    </inertial>
    <visual>
      <origin
        xyz="0 0 0"
        rpy="0 0 0" />
      <geometry>
        <mesh
          filename="package://ARGGG/meshes/Empty_Link3.STL" />
      </geometry>
      <material
        name="">
        <color
          rgba="0.64706 0.61961 0.58431 1" />
      </material>
    </visual>
    <collision>
      <origin
        xyz="0 0 0"
        rpy="0 0 0" />
      <geometry>
        <mesh
          filename="package://ARGGG/meshes/Empty_Link3.STL" />
      </geometry>
    </collision>
  </link>
  <joint
    name="3"
    type="continuous">
    <origin
      xyz="0.01905 0.01524 0.0127"
      rpy="0 0 0.39034" />
    <parent
      link="Empty_Link2" />
    <child
      link="Empty_Link3" />
    <axis
      xyz="0 0 0" />
  </joint>
  <link
    name="Empty_Link4">
    <inertial>
      <origin
        xyz="0.076014 0.061772 -0.09525"
        rpy="0 0 0" />
      <mass
        value="0.098173" />
      <inertia
        ixx="8.1536E-05"
        ixy="1.268E-06"
        ixz="-2.3035E-09"
        iyy="0.00024901"
        iyz="2.143E-11"
        izz="0.00032985" />
    </inertial>
    <visual>
      <origin
        xyz="0 0 0"
        rpy="0 0 0" />
      <geometry>
        <mesh
          filename="package://ARGGG/meshes/Empty_Link4.STL" />
      </geometry>
      <material
        name="">
        <color
          rgba="0.49804 0.49804 0.49804 1" />
      </material>
    </visual>
    <collision>
      <origin
        xyz="0 0 0"
        rpy="0 0 0" />
      <geometry>
        <mesh
          filename="package://ARGGG/meshes/Empty_Link4.STL" />
      </geometry>
    </collision>
  </link>
  <joint
    name="4"
    type="continuous">
    <origin
      xyz="-0.13856 -0.036372 0.00635"
      rpy="0 0 -0.39034" />
    <parent
      link="Empty_Link3" />
    <child
      link="Empty_Link4" />
    <axis
      xyz="0 0 0" />
  </joint>
  <link
    name="Empty_Link5">
    <inertial>
      <origin
        xyz="-0.12443 0.032077 0.16425"
        rpy="0 0 0" />
      <mass
        value="0.45456" />
      <inertia
        ixx="0.00049964"
        ixy="1.3555E-06"
        ixz="-8.2018E-07"
        iyy="0.00023119"
        iyz="-6.6749E-09"
        izz="0.00037855" />
    </inertial>
    <visual>
      <origin
        xyz="0 0 0"
        rpy="0 0 0" />
      <geometry>
        <mesh
          filename="package://ARGGG/meshes/Empty_Link5.STL" />
      </geometry>
      <material
        name="">
        <color
          rgba="0.79216 0.81961 0.92941 1" />
      </material>
    </visual>
    <collision>
      <origin
        xyz="0 0 0"
        rpy="0 0 0" />
      <geometry>
        <mesh
          filename="package://ARGGG/meshes/Empty_Link5.STL" />
      </geometry>
    </collision>
  </link>
  <joint
    name="6"
    type="continuous">
    <origin
      xyz="0.01905 -0.035172 0.069"
      rpy="3.1416 0 3.1416" />
    <parent
      link="Empty_Link4" />
    <child
      link="Empty_Link5" />
    <axis
      xyz="0 0 0" />
  </joint>
  <link
    name="Empty_Link6">
    <inertial>
      <origin
        xyz="0.12427 0.00019692 -0.13575"
        rpy="0 0 0" />
      <mass
        value="0.91903" />
      <inertia
        ixx="0.00092595"
        ixy="-9.1926E-10"
        ixz="-1.6053E-09"
        iyy="0.00092574"
        iyz="-8.2941E-12"
        izz="0.0011242" />
    </inertial>
    <visual>
      <origin
        xyz="0 0 0"
        rpy="0 0 0" />
      <geometry>
        <mesh
          filename="package://ARGGG/meshes/Empty_Link6.STL" />
      </geometry>
      <material
        name="">
        <color
          rgba="0.79216 0.81961 0.92941 1" />
      </material>
    </visual>
    <collision>
      <origin
        xyz="0 0 0"
        rpy="0 0 0" />
      <geometry>
        <mesh
          filename="package://ARGGG/meshes/Empty_Link6.STL" />
      </geometry>
    </collision>
  </link>
  <joint
    name="6"
    type="continuous">
    <origin
      xyz="0 0 0.0285"
      rpy="3.1416 0 3.1416" />
    <parent
      link="Empty_Link5" />
    <child
      link="Empty_Link6" />
    <axis
      xyz="0 0 0" />
  </joint>
</robot> -->